2021-10-06 16:23:12,787: ERROR [/usr/lib/python3/dist-packages/django/utils/log.py: log_response:222], django.request, log, 6274, 140316917102336, Internal Server Error: /avocats_charges/page/1/city/all/search/all-list
Traceback (most recent call last):
  File "/usr/lib/python3/dist-packages/django/db/backends/utils.py", line 84, in _execute
    return self.cursor.execute(sql, params)
psycopg2.errors.UndefinedTable: relation "avocatcharge" does not exist
LINE 1: SELECT COUNT(*) AS "__count" FROM "avocatcharge"
                                          ^


The above exception was the direct cause of the following exception:

Traceback (most recent call last):
  File "/usr/lib/python3/dist-packages/django/core/handlers/exception.py", line 34, in inner
    response = get_response(request)
  File "/usr/lib/python3/dist-packages/django/core/handlers/base.py", line 115, in _get_response
    response = self.process_exception_by_middleware(e, request)
  File "/usr/lib/python3/dist-packages/django/core/handlers/base.py", line 113, in _get_response
    response = wrapped_callback(request, *callback_args, **callback_kwargs)
  File "/home/kali/Projects/Python_Projects/justice_law_office_django/affaires/views.py", line 79, in justice_avocats_charges
    total = AvocatCharge.objects.all().count()
  File "/usr/lib/python3/dist-packages/django/db/models/query.py", line 392, in count
    return self.query.get_count(using=self.db)
  File "/usr/lib/python3/dist-packages/django/db/models/sql/query.py", line 504, in get_count
    number = obj.get_aggregation(using, ['__count'])['__count']
  File "/usr/lib/python3/dist-packages/django/db/models/sql/query.py", line 489, in get_aggregation
    result = compiler.execute_sql(SINGLE)
  File "/usr/lib/python3/dist-packages/django/db/models/sql/compiler.py", line 1142, in execute_sql
    cursor.execute(sql, params)
  File "/usr/lib/python3/dist-packages/django/db/backends/utils.py", line 99, in execute
    return super().execute(sql, params)
  File "/usr/lib/python3/dist-packages/django/db/backends/utils.py", line 67, in execute
    return self._execute_with_wrappers(sql, params, many=False, executor=self._execute)
  File "/usr/lib/python3/dist-packages/django/db/backends/utils.py", line 76, in _execute_with_wrappers
    return executor(sql, params, many, context)
  File "/usr/lib/python3/dist-packages/django/db/backends/utils.py", line 84, in _execute
    return self.cursor.execute(sql, params)
  File "/usr/lib/python3/dist-packages/django/db/utils.py", line 89, in __exit__
    raise dj_exc_value.with_traceback(traceback) from exc_value
  File "/usr/lib/python3/dist-packages/django/db/backends/utils.py", line 84, in _execute
    return self.cursor.execute(sql, params)
django.db.utils.ProgrammingError: relation "avocatcharge" does not exist
LINE 1: SELECT COUNT(*) AS "__count" FROM "avocatcharge"
                                          ^

2021-10-06 16:24:01,646: ERROR [/usr/lib/python3/dist-packages/django/utils/log.py: log_response:222], django.request, log, 6274, 140316917102336, Internal Server Error: /avocats_charges/page/1/city/all/search/all-list
Traceback (most recent call last):
  File "/usr/lib/python3/dist-packages/django/core/handlers/exception.py", line 34, in inner
    response = get_response(request)
  File "/usr/lib/python3/dist-packages/django/core/handlers/base.py", line 115, in _get_response
    response = self.process_exception_by_middleware(e, request)
  File "/usr/lib/python3/dist-packages/django/core/handlers/base.py", line 113, in _get_response
    response = wrapped_callback(request, *callback_args, **callback_kwargs)
  File "/home/kali/Projects/Python_Projects/justice_law_office_django/affaires/views.py", line 80, in justice_avocats_charges
    avocats_charges = AvocatCharge.objects.annotate(
  File "/usr/lib/python3/dist-packages/django/db/models/manager.py", line 82, in manager_method
    return getattr(self.get_queryset(), name)(*args, **kwargs)
  File "/usr/lib/python3/dist-packages/django/db/models/query.py", line 1056, in annotate
    clone.query.add_annotation(annotation, alias, is_summary=False)
  File "/usr/lib/python3/dist-packages/django/db/models/sql/query.py", line 999, in add_annotation
    annotation = annotation.resolve_expression(self, allow_joins=True, reuse=None,
  File "/usr/lib/python3/dist-packages/django/contrib/postgres/search.py", line 62, in resolve_expression
    resolved = super().resolve_expression(query, allow_joins, reuse, summarize, for_save)
  File "/usr/lib/python3/dist-packages/django/db/models/expressions.py", line 603, in resolve_expression
    c.source_expressions[pos] = arg.resolve_expression(query, allow_joins, reuse, summarize, for_save)
  File "/usr/lib/python3/dist-packages/django/db/models/expressions.py", line 514, in resolve_expression
    return query.resolve_ref(self.name, allow_joins, reuse, summarize, simple_col)
  File "/usr/lib/python3/dist-packages/django/db/models/sql/query.py", line 1601, in resolve_ref
    join_info = self.setup_joins(field_list, self.get_meta(), self.get_initial_alias(), can_reuse=reuse)
  File "/usr/lib/python3/dist-packages/django/db/models/sql/query.py", line 1503, in setup_joins
    path, final_field, targets, rest = self.names_to_path(
  File "/usr/lib/python3/dist-packages/django/db/models/sql/query.py", line 1419, in names_to_path
    raise FieldError("Cannot resolve keyword '%s' into field. "
django.core.exceptions.FieldError: Cannot resolve keyword 'cabinet' into field. Choices are: adresse, created_at, email, gsm, id, nom, observation, prenom, sexe, slug, tel, updated_at, ville
