2021-10-06 16:23:12,787: ERROR [/usr/lib/python3/dist-packages/django/utils/log.py: log_response:222], django.request, log, 6274, 140316917102336, Internal Server Error: /avocats_charges/page/1/city/all/search/all-list
Traceback (most recent call last):
  File "/usr/lib/python3/dist-packages/django/db/backends/utils.py", line 84, in _execute
    return self.cursor.execute(sql, params)
psycopg2.errors.UndefinedTable: relation "avocatcharge" does not exist
LINE 1: SELECT COUNT(*) AS "__count" FROM "avocatcharge"
                                          ^


The above exception was the direct cause of the following exception:

Traceback (most recent call last):
  File "/usr/lib/python3/dist-packages/django/core/handlers/exception.py", line 34, in inner
    response = get_response(request)
  File "/usr/lib/python3/dist-packages/django/core/handlers/base.py", line 115, in _get_response
    response = self.process_exception_by_middleware(e, request)
  File "/usr/lib/python3/dist-packages/django/core/handlers/base.py", line 113, in _get_response
    response = wrapped_callback(request, *callback_args, **callback_kwargs)
  File "/home/kali/Projects/Python_Projects/justice_law_office_django/affaires/views.py", line 79, in justice_avocats_charges
    total = AvocatCharge.objects.all().count()
  File "/usr/lib/python3/dist-packages/django/db/models/query.py", line 392, in count
    return self.query.get_count(using=self.db)
  File "/usr/lib/python3/dist-packages/django/db/models/sql/query.py", line 504, in get_count
    number = obj.get_aggregation(using, ['__count'])['__count']
  File "/usr/lib/python3/dist-packages/django/db/models/sql/query.py", line 489, in get_aggregation
    result = compiler.execute_sql(SINGLE)
  File "/usr/lib/python3/dist-packages/django/db/models/sql/compiler.py", line 1142, in execute_sql
    cursor.execute(sql, params)
  File "/usr/lib/python3/dist-packages/django/db/backends/utils.py", line 99, in execute
    return super().execute(sql, params)
  File "/usr/lib/python3/dist-packages/django/db/backends/utils.py", line 67, in execute
    return self._execute_with_wrappers(sql, params, many=False, executor=self._execute)
  File "/usr/lib/python3/dist-packages/django/db/backends/utils.py", line 76, in _execute_with_wrappers
    return executor(sql, params, many, context)
  File "/usr/lib/python3/dist-packages/django/db/backends/utils.py", line 84, in _execute
    return self.cursor.execute(sql, params)
  File "/usr/lib/python3/dist-packages/django/db/utils.py", line 89, in __exit__
    raise dj_exc_value.with_traceback(traceback) from exc_value
  File "/usr/lib/python3/dist-packages/django/db/backends/utils.py", line 84, in _execute
    return self.cursor.execute(sql, params)
django.db.utils.ProgrammingError: relation "avocatcharge" does not exist
LINE 1: SELECT COUNT(*) AS "__count" FROM "avocatcharge"
                                          ^

2021-10-06 16:24:01,646: ERROR [/usr/lib/python3/dist-packages/django/utils/log.py: log_response:222], django.request, log, 6274, 140316917102336, Internal Server Error: /avocats_charges/page/1/city/all/search/all-list
Traceback (most recent call last):
  File "/usr/lib/python3/dist-packages/django/core/handlers/exception.py", line 34, in inner
    response = get_response(request)
  File "/usr/lib/python3/dist-packages/django/core/handlers/base.py", line 115, in _get_response
    response = self.process_exception_by_middleware(e, request)
  File "/usr/lib/python3/dist-packages/django/core/handlers/base.py", line 113, in _get_response
    response = wrapped_callback(request, *callback_args, **callback_kwargs)
  File "/home/kali/Projects/Python_Projects/justice_law_office_django/affaires/views.py", line 80, in justice_avocats_charges
    avocats_charges = AvocatCharge.objects.annotate(
  File "/usr/lib/python3/dist-packages/django/db/models/manager.py", line 82, in manager_method
    return getattr(self.get_queryset(), name)(*args, **kwargs)
  File "/usr/lib/python3/dist-packages/django/db/models/query.py", line 1056, in annotate
    clone.query.add_annotation(annotation, alias, is_summary=False)
  File "/usr/lib/python3/dist-packages/django/db/models/sql/query.py", line 999, in add_annotation
    annotation = annotation.resolve_expression(self, allow_joins=True, reuse=None,
  File "/usr/lib/python3/dist-packages/django/contrib/postgres/search.py", line 62, in resolve_expression
    resolved = super().resolve_expression(query, allow_joins, reuse, summarize, for_save)
  File "/usr/lib/python3/dist-packages/django/db/models/expressions.py", line 603, in resolve_expression
    c.source_expressions[pos] = arg.resolve_expression(query, allow_joins, reuse, summarize, for_save)
  File "/usr/lib/python3/dist-packages/django/db/models/expressions.py", line 514, in resolve_expression
    return query.resolve_ref(self.name, allow_joins, reuse, summarize, simple_col)
  File "/usr/lib/python3/dist-packages/django/db/models/sql/query.py", line 1601, in resolve_ref
    join_info = self.setup_joins(field_list, self.get_meta(), self.get_initial_alias(), can_reuse=reuse)
  File "/usr/lib/python3/dist-packages/django/db/models/sql/query.py", line 1503, in setup_joins
    path, final_field, targets, rest = self.names_to_path(
  File "/usr/lib/python3/dist-packages/django/db/models/sql/query.py", line 1419, in names_to_path
    raise FieldError("Cannot resolve keyword '%s' into field. "
django.core.exceptions.FieldError: Cannot resolve keyword 'cabinet' into field. Choices are: adresse, created_at, email, gsm, id, nom, observation, prenom, sexe, slug, tel, updated_at, ville
2021-10-07 09:48:38,900: ERROR [/usr/lib/python3/dist-packages/django/utils/log.py: log_response:222], django.request, log, 1918, 139857396610816, Internal Server Error: /
Traceback (most recent call last):
  File "/usr/lib/python3/dist-packages/django/core/handlers/exception.py", line 34, in inner
    response = get_response(request)
  File "/usr/lib/python3/dist-packages/django/core/handlers/base.py", line 115, in _get_response
    response = self.process_exception_by_middleware(e, request)
  File "/usr/lib/python3/dist-packages/django/core/handlers/base.py", line 113, in _get_response
    response = wrapped_callback(request, *callback_args, **callback_kwargs)
  File "/home/kali/Projects/Python_Projects/justice_law_office_django/justice/views.py", line 13, in index
    return render(request=request, template_name=template_name, context=context)
  File "/usr/lib/python3/dist-packages/django/shortcuts.py", line 36, in render
    content = loader.render_to_string(template_name, context, request, using=using)
  File "/usr/lib/python3/dist-packages/django/template/loader.py", line 62, in render_to_string
    return template.render(context, request)
  File "/usr/lib/python3/dist-packages/django/template/backends/django.py", line 61, in render
    return self.template.render(context)
  File "/usr/lib/python3/dist-packages/django/template/base.py", line 171, in render
    return self._render(context)
  File "/usr/lib/python3/dist-packages/django/template/base.py", line 163, in _render
    return self.nodelist.render(context)
  File "/usr/lib/python3/dist-packages/django/template/base.py", line 937, in render
    bit = node.render_annotated(context)
  File "/usr/lib/python3/dist-packages/django/template/base.py", line 904, in render_annotated
    return self.render(context)
  File "/usr/lib/python3/dist-packages/django/template/loader_tags.py", line 150, in render
    return compiled_parent._render(context)
  File "/usr/lib/python3/dist-packages/django/template/base.py", line 163, in _render
    return self.nodelist.render(context)
  File "/usr/lib/python3/dist-packages/django/template/base.py", line 937, in render
    bit = node.render_annotated(context)
  File "/usr/lib/python3/dist-packages/django/template/base.py", line 904, in render_annotated
    return self.render(context)
  File "/usr/lib/python3/dist-packages/django/template/loader_tags.py", line 150, in render
    return compiled_parent._render(context)
  File "/usr/lib/python3/dist-packages/django/template/base.py", line 163, in _render
    return self.nodelist.render(context)
  File "/usr/lib/python3/dist-packages/django/template/base.py", line 937, in render
    bit = node.render_annotated(context)
  File "/usr/lib/python3/dist-packages/django/template/base.py", line 904, in render_annotated
    return self.render(context)
  File "/usr/lib/python3/dist-packages/django/template/loader_tags.py", line 62, in render
    result = block.nodelist.render(context)
  File "/usr/lib/python3/dist-packages/django/template/base.py", line 937, in render
    bit = node.render_annotated(context)
  File "/usr/lib/python3/dist-packages/django/template/base.py", line 904, in render_annotated
    return self.render(context)
  File "/usr/lib/python3/dist-packages/django/template/defaulttags.py", line 443, in render
    url = reverse(view_name, args=args, kwargs=kwargs, current_app=current_app)
  File "/usr/lib/python3/dist-packages/django/urls/base.py", line 90, in reverse
    return iri_to_uri(resolver._reverse_with_prefix(view, prefix, *args, **kwargs))
  File "/usr/lib/python3/dist-packages/django/urls/resolvers.py", line 673, in _reverse_with_prefix
    raise NoReverseMatch(msg)
django.urls.exceptions.NoReverseMatch: Reverse for '' not found. '' is not a valid view function or pattern name.
2021-10-07 09:48:45,696: ERROR [/usr/lib/python3/dist-packages/django/utils/log.py: log_response:222], django.request, log, 1918, 139857396610816, Internal Server Error: /
Traceback (most recent call last):
  File "/usr/lib/python3/dist-packages/django/core/handlers/exception.py", line 34, in inner
    response = get_response(request)
  File "/usr/lib/python3/dist-packages/django/core/handlers/base.py", line 115, in _get_response
    response = self.process_exception_by_middleware(e, request)
  File "/usr/lib/python3/dist-packages/django/core/handlers/base.py", line 113, in _get_response
    response = wrapped_callback(request, *callback_args, **callback_kwargs)
  File "/home/kali/Projects/Python_Projects/justice_law_office_django/justice/views.py", line 13, in index
    return render(request=request, template_name=template_name, context=context)
  File "/usr/lib/python3/dist-packages/django/shortcuts.py", line 36, in render
    content = loader.render_to_string(template_name, context, request, using=using)
  File "/usr/lib/python3/dist-packages/django/template/loader.py", line 62, in render_to_string
    return template.render(context, request)
  File "/usr/lib/python3/dist-packages/django/template/backends/django.py", line 61, in render
    return self.template.render(context)
  File "/usr/lib/python3/dist-packages/django/template/base.py", line 171, in render
    return self._render(context)
  File "/usr/lib/python3/dist-packages/django/template/base.py", line 163, in _render
    return self.nodelist.render(context)
  File "/usr/lib/python3/dist-packages/django/template/base.py", line 937, in render
    bit = node.render_annotated(context)
  File "/usr/lib/python3/dist-packages/django/template/base.py", line 904, in render_annotated
    return self.render(context)
  File "/usr/lib/python3/dist-packages/django/template/loader_tags.py", line 150, in render
    return compiled_parent._render(context)
  File "/usr/lib/python3/dist-packages/django/template/base.py", line 163, in _render
    return self.nodelist.render(context)
  File "/usr/lib/python3/dist-packages/django/template/base.py", line 937, in render
    bit = node.render_annotated(context)
  File "/usr/lib/python3/dist-packages/django/template/base.py", line 904, in render_annotated
    return self.render(context)
  File "/usr/lib/python3/dist-packages/django/template/loader_tags.py", line 150, in render
    return compiled_parent._render(context)
  File "/usr/lib/python3/dist-packages/django/template/base.py", line 163, in _render
    return self.nodelist.render(context)
  File "/usr/lib/python3/dist-packages/django/template/base.py", line 937, in render
    bit = node.render_annotated(context)
  File "/usr/lib/python3/dist-packages/django/template/base.py", line 904, in render_annotated
    return self.render(context)
  File "/usr/lib/python3/dist-packages/django/template/loader_tags.py", line 62, in render
    result = block.nodelist.render(context)
  File "/usr/lib/python3/dist-packages/django/template/base.py", line 937, in render
    bit = node.render_annotated(context)
  File "/usr/lib/python3/dist-packages/django/template/base.py", line 904, in render_annotated
    return self.render(context)
  File "/usr/lib/python3/dist-packages/django/template/defaulttags.py", line 443, in render
    url = reverse(view_name, args=args, kwargs=kwargs, current_app=current_app)
  File "/usr/lib/python3/dist-packages/django/urls/base.py", line 90, in reverse
    return iri_to_uri(resolver._reverse_with_prefix(view, prefix, *args, **kwargs))
  File "/usr/lib/python3/dist-packages/django/urls/resolvers.py", line 673, in _reverse_with_prefix
    raise NoReverseMatch(msg)
django.urls.exceptions.NoReverseMatch: Reverse for '' not found. '' is not a valid view function or pattern name.
2021-10-07 09:49:11,176: ERROR [/usr/lib/python3/dist-packages/django/utils/log.py: log_response:222], django.request, log, 1935, 140263327020800, Internal Server Error: /
Traceback (most recent call last):
  File "/usr/lib/python3/dist-packages/django/core/handlers/exception.py", line 34, in inner
    response = get_response(request)
  File "/usr/lib/python3/dist-packages/django/core/handlers/base.py", line 115, in _get_response
    response = self.process_exception_by_middleware(e, request)
  File "/usr/lib/python3/dist-packages/django/core/handlers/base.py", line 113, in _get_response
    response = wrapped_callback(request, *callback_args, **callback_kwargs)
  File "/home/kali/Projects/Python_Projects/justice_law_office_django/justice/views.py", line 13, in index
    return render(request=request, template_name=template_name, context=context)
  File "/usr/lib/python3/dist-packages/django/shortcuts.py", line 36, in render
    content = loader.render_to_string(template_name, context, request, using=using)
  File "/usr/lib/python3/dist-packages/django/template/loader.py", line 62, in render_to_string
    return template.render(context, request)
  File "/usr/lib/python3/dist-packages/django/template/backends/django.py", line 61, in render
    return self.template.render(context)
  File "/usr/lib/python3/dist-packages/django/template/base.py", line 171, in render
    return self._render(context)
  File "/usr/lib/python3/dist-packages/django/template/base.py", line 163, in _render
    return self.nodelist.render(context)
  File "/usr/lib/python3/dist-packages/django/template/base.py", line 937, in render
    bit = node.render_annotated(context)
  File "/usr/lib/python3/dist-packages/django/template/base.py", line 904, in render_annotated
    return self.render(context)
  File "/usr/lib/python3/dist-packages/django/template/loader_tags.py", line 150, in render
    return compiled_parent._render(context)
  File "/usr/lib/python3/dist-packages/django/template/base.py", line 163, in _render
    return self.nodelist.render(context)
  File "/usr/lib/python3/dist-packages/django/template/base.py", line 937, in render
    bit = node.render_annotated(context)
  File "/usr/lib/python3/dist-packages/django/template/base.py", line 904, in render_annotated
    return self.render(context)
  File "/usr/lib/python3/dist-packages/django/template/loader_tags.py", line 150, in render
    return compiled_parent._render(context)
  File "/usr/lib/python3/dist-packages/django/template/base.py", line 163, in _render
    return self.nodelist.render(context)
  File "/usr/lib/python3/dist-packages/django/template/base.py", line 937, in render
    bit = node.render_annotated(context)
  File "/usr/lib/python3/dist-packages/django/template/base.py", line 904, in render_annotated
    return self.render(context)
  File "/usr/lib/python3/dist-packages/django/template/loader_tags.py", line 62, in render
    result = block.nodelist.render(context)
  File "/usr/lib/python3/dist-packages/django/template/base.py", line 937, in render
    bit = node.render_annotated(context)
  File "/usr/lib/python3/dist-packages/django/template/base.py", line 904, in render_annotated
    return self.render(context)
  File "/usr/lib/python3/dist-packages/django/template/defaulttags.py", line 443, in render
    url = reverse(view_name, args=args, kwargs=kwargs, current_app=current_app)
  File "/usr/lib/python3/dist-packages/django/urls/base.py", line 90, in reverse
    return iri_to_uri(resolver._reverse_with_prefix(view, prefix, *args, **kwargs))
  File "/usr/lib/python3/dist-packages/django/urls/resolvers.py", line 673, in _reverse_with_prefix
    raise NoReverseMatch(msg)
django.urls.exceptions.NoReverseMatch: Reverse for '' not found. '' is not a valid view function or pattern name.
2021-10-07 10:07:19,521: ERROR [/usr/lib/python3/dist-packages/django/utils/log.py: log_response:222], django.request, log, 2136, 139792863721216, Internal Server Error: /
Traceback (most recent call last):
  File "/usr/lib/python3/dist-packages/django/core/handlers/exception.py", line 34, in inner
    response = get_response(request)
  File "/usr/lib/python3/dist-packages/django/core/handlers/base.py", line 115, in _get_response
    response = self.process_exception_by_middleware(e, request)
  File "/usr/lib/python3/dist-packages/django/core/handlers/base.py", line 113, in _get_response
    response = wrapped_callback(request, *callback_args, **callback_kwargs)
  File "/home/kali/Projects/Python_Projects/justice_law_office_django/justice/views.py", line 13, in index
    return render(request=request, template_name=template_name, context=context)
  File "/usr/lib/python3/dist-packages/django/shortcuts.py", line 36, in render
    content = loader.render_to_string(template_name, context, request, using=using)
  File "/usr/lib/python3/dist-packages/django/template/loader.py", line 62, in render_to_string
    return template.render(context, request)
  File "/usr/lib/python3/dist-packages/django/template/backends/django.py", line 61, in render
    return self.template.render(context)
  File "/usr/lib/python3/dist-packages/django/template/base.py", line 171, in render
    return self._render(context)
  File "/usr/lib/python3/dist-packages/django/template/base.py", line 163, in _render
    return self.nodelist.render(context)
  File "/usr/lib/python3/dist-packages/django/template/base.py", line 937, in render
    bit = node.render_annotated(context)
  File "/usr/lib/python3/dist-packages/django/template/base.py", line 904, in render_annotated
    return self.render(context)
  File "/usr/lib/python3/dist-packages/django/template/loader_tags.py", line 150, in render
    return compiled_parent._render(context)
  File "/usr/lib/python3/dist-packages/django/template/base.py", line 163, in _render
    return self.nodelist.render(context)
  File "/usr/lib/python3/dist-packages/django/template/base.py", line 937, in render
    bit = node.render_annotated(context)
  File "/usr/lib/python3/dist-packages/django/template/base.py", line 904, in render_annotated
    return self.render(context)
  File "/usr/lib/python3/dist-packages/django/template/loader_tags.py", line 150, in render
    return compiled_parent._render(context)
  File "/usr/lib/python3/dist-packages/django/template/base.py", line 163, in _render
    return self.nodelist.render(context)
  File "/usr/lib/python3/dist-packages/django/template/base.py", line 937, in render
    bit = node.render_annotated(context)
  File "/usr/lib/python3/dist-packages/django/template/base.py", line 904, in render_annotated
    return self.render(context)
  File "/usr/lib/python3/dist-packages/django/template/loader_tags.py", line 62, in render
    result = block.nodelist.render(context)
  File "/usr/lib/python3/dist-packages/django/template/base.py", line 937, in render
    bit = node.render_annotated(context)
  File "/usr/lib/python3/dist-packages/django/template/base.py", line 904, in render_annotated
    return self.render(context)
  File "/usr/lib/python3/dist-packages/django/template/defaulttags.py", line 443, in render
    url = reverse(view_name, args=args, kwargs=kwargs, current_app=current_app)
  File "/usr/lib/python3/dist-packages/django/urls/base.py", line 90, in reverse
    return iri_to_uri(resolver._reverse_with_prefix(view, prefix, *args, **kwargs))
  File "/usr/lib/python3/dist-packages/django/urls/resolvers.py", line 673, in _reverse_with_prefix
    raise NoReverseMatch(msg)
django.urls.exceptions.NoReverseMatch: Reverse for 'justice_clients_all' not found. 'justice_clients_all' is not a valid view function or pattern name.
2021-10-07 10:07:29,862: ERROR [/usr/lib/python3/dist-packages/django/utils/log.py: log_response:222], django.request, log, 2141, 139678855427840, Internal Server Error: /
Traceback (most recent call last):
  File "/usr/lib/python3/dist-packages/django/core/handlers/exception.py", line 34, in inner
    response = get_response(request)
  File "/usr/lib/python3/dist-packages/django/core/handlers/base.py", line 115, in _get_response
    response = self.process_exception_by_middleware(e, request)
  File "/usr/lib/python3/dist-packages/django/core/handlers/base.py", line 113, in _get_response
    response = wrapped_callback(request, *callback_args, **callback_kwargs)
  File "/home/kali/Projects/Python_Projects/justice_law_office_django/justice/views.py", line 13, in index
    return render(request=request, template_name=template_name, context=context)
  File "/usr/lib/python3/dist-packages/django/shortcuts.py", line 36, in render
    content = loader.render_to_string(template_name, context, request, using=using)
  File "/usr/lib/python3/dist-packages/django/template/loader.py", line 62, in render_to_string
    return template.render(context, request)
  File "/usr/lib/python3/dist-packages/django/template/backends/django.py", line 61, in render
    return self.template.render(context)
  File "/usr/lib/python3/dist-packages/django/template/base.py", line 171, in render
    return self._render(context)
  File "/usr/lib/python3/dist-packages/django/template/base.py", line 163, in _render
    return self.nodelist.render(context)
  File "/usr/lib/python3/dist-packages/django/template/base.py", line 937, in render
    bit = node.render_annotated(context)
  File "/usr/lib/python3/dist-packages/django/template/base.py", line 904, in render_annotated
    return self.render(context)
  File "/usr/lib/python3/dist-packages/django/template/loader_tags.py", line 150, in render
    return compiled_parent._render(context)
  File "/usr/lib/python3/dist-packages/django/template/base.py", line 163, in _render
    return self.nodelist.render(context)
  File "/usr/lib/python3/dist-packages/django/template/base.py", line 937, in render
    bit = node.render_annotated(context)
  File "/usr/lib/python3/dist-packages/django/template/base.py", line 904, in render_annotated
    return self.render(context)
  File "/usr/lib/python3/dist-packages/django/template/loader_tags.py", line 150, in render
    return compiled_parent._render(context)
  File "/usr/lib/python3/dist-packages/django/template/base.py", line 163, in _render
    return self.nodelist.render(context)
  File "/usr/lib/python3/dist-packages/django/template/base.py", line 937, in render
    bit = node.render_annotated(context)
  File "/usr/lib/python3/dist-packages/django/template/base.py", line 904, in render_annotated
    return self.render(context)
  File "/usr/lib/python3/dist-packages/django/template/loader_tags.py", line 62, in render
    result = block.nodelist.render(context)
  File "/usr/lib/python3/dist-packages/django/template/base.py", line 937, in render
    bit = node.render_annotated(context)
  File "/usr/lib/python3/dist-packages/django/template/base.py", line 904, in render_annotated
    return self.render(context)
  File "/usr/lib/python3/dist-packages/django/template/defaulttags.py", line 443, in render
    url = reverse(view_name, args=args, kwargs=kwargs, current_app=current_app)
  File "/usr/lib/python3/dist-packages/django/urls/base.py", line 90, in reverse
    return iri_to_uri(resolver._reverse_with_prefix(view, prefix, *args, **kwargs))
  File "/usr/lib/python3/dist-packages/django/urls/resolvers.py", line 673, in _reverse_with_prefix
    raise NoReverseMatch(msg)
django.urls.exceptions.NoReverseMatch: Reverse for '' not found. '' is not a valid view function or pattern name.
2021-10-07 14:51:21,965: ERROR [/usr/lib/python3/dist-packages/django/utils/log.py: log_response:222], django.request, log, 3719, 140309646497536, Internal Server Error: /departements/page/1/search/all-list
Traceback (most recent call last):
  File "/usr/lib/python3/dist-packages/django/db/backends/utils.py", line 84, in _execute
    return self.cursor.execute(sql, params)
psycopg2.errors.UndefinedTable: relation "departement" does not exist
LINE 1: ...ALESCE("departement"."nom", '')) AS "search" FROM "departeme...
                                                             ^


The above exception was the direct cause of the following exception:

Traceback (most recent call last):
  File "/usr/lib/python3/dist-packages/django/core/handlers/exception.py", line 34, in inner
    response = get_response(request)
  File "/usr/lib/python3/dist-packages/django/core/handlers/base.py", line 115, in _get_response
    response = self.process_exception_by_middleware(e, request)
  File "/usr/lib/python3/dist-packages/django/core/handlers/base.py", line 113, in _get_response
    response = wrapped_callback(request, *callback_args, **callback_kwargs)
  File "/home/kali/Projects/Python_Projects/justice_law_office_django/affaires/views.py", line 256, in departements_views
    departements = paginator.page(page)
  File "/usr/lib/python3/dist-packages/django/core/paginator.py", line 70, in page
    number = self.validate_number(number)
  File "/usr/lib/python3/dist-packages/django/core/paginator.py", line 48, in validate_number
    if number > self.num_pages:
  File "/usr/lib/python3/dist-packages/django/utils/functional.py", line 80, in __get__
    res = instance.__dict__[self.name] = self.func(instance)
  File "/usr/lib/python3/dist-packages/django/core/paginator.py", line 97, in num_pages
    if self.count == 0 and not self.allow_empty_first_page:
  File "/usr/lib/python3/dist-packages/django/utils/functional.py", line 80, in __get__
    res = instance.__dict__[self.name] = self.func(instance)
  File "/usr/lib/python3/dist-packages/django/core/paginator.py", line 91, in count
    return c()
  File "/usr/lib/python3/dist-packages/django/db/models/query.py", line 392, in count
    return self.query.get_count(using=self.db)
  File "/usr/lib/python3/dist-packages/django/db/models/sql/query.py", line 504, in get_count
    number = obj.get_aggregation(using, ['__count'])['__count']
  File "/usr/lib/python3/dist-packages/django/db/models/sql/query.py", line 489, in get_aggregation
    result = compiler.execute_sql(SINGLE)
  File "/usr/lib/python3/dist-packages/django/db/models/sql/compiler.py", line 1142, in execute_sql
    cursor.execute(sql, params)
  File "/usr/lib/python3/dist-packages/django/db/backends/utils.py", line 99, in execute
    return super().execute(sql, params)
  File "/usr/lib/python3/dist-packages/django/db/backends/utils.py", line 67, in execute
    return self._execute_with_wrappers(sql, params, many=False, executor=self._execute)
  File "/usr/lib/python3/dist-packages/django/db/backends/utils.py", line 76, in _execute_with_wrappers
    return executor(sql, params, many, context)
  File "/usr/lib/python3/dist-packages/django/db/backends/utils.py", line 84, in _execute
    return self.cursor.execute(sql, params)
  File "/usr/lib/python3/dist-packages/django/db/utils.py", line 89, in __exit__
    raise dj_exc_value.with_traceback(traceback) from exc_value
  File "/usr/lib/python3/dist-packages/django/db/backends/utils.py", line 84, in _execute
    return self.cursor.execute(sql, params)
django.db.utils.ProgrammingError: relation "departement" does not exist
LINE 1: ...ALESCE("departement"."nom", '')) AS "search" FROM "departeme...
                                                             ^

2021-10-07 15:35:26,342: ERROR [/usr/lib/python3/dist-packages/django/utils/log.py: log_response:222], django.request, log, 4405, 140012882216704, Internal Server Error: /departements/page/1/search/all-list
Traceback (most recent call last):
  File "/usr/lib/python3/dist-packages/django/core/handlers/exception.py", line 34, in inner
    response = get_response(request)
  File "/usr/lib/python3/dist-packages/django/core/handlers/base.py", line 115, in _get_response
    response = self.process_exception_by_middleware(e, request)
  File "/usr/lib/python3/dist-packages/django/core/handlers/base.py", line 113, in _get_response
    response = wrapped_callback(request, *callback_args, **callback_kwargs)
  File "/home/kali/Projects/Python_Projects/justice_law_office_django/affaires/views.py", line 246, in departements_views
    departements = Departement.objects.annotate(
  File "/usr/lib/python3/dist-packages/django/db/models/manager.py", line 82, in manager_method
    return getattr(self.get_queryset(), name)(*args, **kwargs)
  File "/usr/lib/python3/dist-packages/django/db/models/query.py", line 1056, in annotate
    clone.query.add_annotation(annotation, alias, is_summary=False)
  File "/usr/lib/python3/dist-packages/django/db/models/sql/query.py", line 999, in add_annotation
    annotation = annotation.resolve_expression(self, allow_joins=True, reuse=None,
  File "/usr/lib/python3/dist-packages/django/contrib/postgres/search.py", line 62, in resolve_expression
    resolved = super().resolve_expression(query, allow_joins, reuse, summarize, for_save)
  File "/usr/lib/python3/dist-packages/django/db/models/expressions.py", line 603, in resolve_expression
    c.source_expressions[pos] = arg.resolve_expression(query, allow_joins, reuse, summarize, for_save)
  File "/usr/lib/python3/dist-packages/django/db/models/expressions.py", line 514, in resolve_expression
    return query.resolve_ref(self.name, allow_joins, reuse, summarize, simple_col)
  File "/usr/lib/python3/dist-packages/django/db/models/sql/query.py", line 1601, in resolve_ref
    join_info = self.setup_joins(field_list, self.get_meta(), self.get_initial_alias(), can_reuse=reuse)
  File "/usr/lib/python3/dist-packages/django/db/models/sql/query.py", line 1503, in setup_joins
    path, final_field, targets, rest = self.names_to_path(
  File "/usr/lib/python3/dist-packages/django/db/models/sql/query.py", line 1419, in names_to_path
    raise FieldError("Cannot resolve keyword '%s' into field. "
django.core.exceptions.FieldError: Cannot resolve keyword 'nom' into field. Choices are: affaire, id, nom_depart
2021-10-07 15:36:23,960: ERROR [/usr/lib/python3/dist-packages/django/utils/log.py: log_response:222], django.request, log, 4448, 140674137585408, Internal Server Error: /departements/page/1/search/all-list
Traceback (most recent call last):
  File "/usr/lib/python3/dist-packages/django/db/backends/utils.py", line 84, in _execute
    return self.cursor.execute(sql, params)
psycopg2.errors.UndefinedColumn: column departement.nom_depart does not exist
LINE 1: ... "departement"."id" AS Col1, to_tsvector(COALESCE("departeme...
                                                             ^


The above exception was the direct cause of the following exception:

Traceback (most recent call last):
  File "/usr/lib/python3/dist-packages/django/core/handlers/exception.py", line 34, in inner
    response = get_response(request)
  File "/usr/lib/python3/dist-packages/django/core/handlers/base.py", line 115, in _get_response
    response = self.process_exception_by_middleware(e, request)
  File "/usr/lib/python3/dist-packages/django/core/handlers/base.py", line 113, in _get_response
    response = wrapped_callback(request, *callback_args, **callback_kwargs)
  File "/home/kali/Projects/Python_Projects/justice_law_office_django/affaires/views.py", line 256, in departements_views
    departements = paginator.page(page)
  File "/usr/lib/python3/dist-packages/django/core/paginator.py", line 70, in page
    number = self.validate_number(number)
  File "/usr/lib/python3/dist-packages/django/core/paginator.py", line 48, in validate_number
    if number > self.num_pages:
  File "/usr/lib/python3/dist-packages/django/utils/functional.py", line 80, in __get__
    res = instance.__dict__[self.name] = self.func(instance)
  File "/usr/lib/python3/dist-packages/django/core/paginator.py", line 97, in num_pages
    if self.count == 0 and not self.allow_empty_first_page:
  File "/usr/lib/python3/dist-packages/django/utils/functional.py", line 80, in __get__
    res = instance.__dict__[self.name] = self.func(instance)
  File "/usr/lib/python3/dist-packages/django/core/paginator.py", line 91, in count
    return c()
  File "/usr/lib/python3/dist-packages/django/db/models/query.py", line 392, in count
    return self.query.get_count(using=self.db)
  File "/usr/lib/python3/dist-packages/django/db/models/sql/query.py", line 504, in get_count
    number = obj.get_aggregation(using, ['__count'])['__count']
  File "/usr/lib/python3/dist-packages/django/db/models/sql/query.py", line 489, in get_aggregation
    result = compiler.execute_sql(SINGLE)
  File "/usr/lib/python3/dist-packages/django/db/models/sql/compiler.py", line 1142, in execute_sql
    cursor.execute(sql, params)
  File "/usr/lib/python3/dist-packages/django/db/backends/utils.py", line 99, in execute
    return super().execute(sql, params)
  File "/usr/lib/python3/dist-packages/django/db/backends/utils.py", line 67, in execute
    return self._execute_with_wrappers(sql, params, many=False, executor=self._execute)
  File "/usr/lib/python3/dist-packages/django/db/backends/utils.py", line 76, in _execute_with_wrappers
    return executor(sql, params, many, context)
  File "/usr/lib/python3/dist-packages/django/db/backends/utils.py", line 84, in _execute
    return self.cursor.execute(sql, params)
  File "/usr/lib/python3/dist-packages/django/db/utils.py", line 89, in __exit__
    raise dj_exc_value.with_traceback(traceback) from exc_value
  File "/usr/lib/python3/dist-packages/django/db/backends/utils.py", line 84, in _execute
    return self.cursor.execute(sql, params)
django.db.utils.ProgrammingError: column departement.nom_depart does not exist
LINE 1: ... "departement"."id" AS Col1, to_tsvector(COALESCE("departeme...
                                                             ^

2021-10-07 15:52:53,992: ERROR [/usr/lib/python3/dist-packages/django/utils/log.py: log_response:222], django.request, log, 4540, 140339053061888, Internal Server Error: /departements/create
Traceback (most recent call last):
  File "/usr/lib/python3/dist-packages/django/core/handlers/exception.py", line 34, in inner
    response = get_response(request)
  File "/usr/lib/python3/dist-packages/django/core/handlers/base.py", line 115, in _get_response
    response = self.process_exception_by_middleware(e, request)
  File "/usr/lib/python3/dist-packages/django/core/handlers/base.py", line 113, in _get_response
    response = wrapped_callback(request, *callback_args, **callback_kwargs)
  File "/home/kali/Projects/Python_Projects/justice_law_office_django/affaires/views.py", line 316, in departement_form
    print('form.is_valid(): ', form.is_valid())
  File "/usr/lib/python3/dist-packages/django/forms/forms.py", line 185, in is_valid
    return self.is_bound and not self.errors
  File "/usr/lib/python3/dist-packages/django/forms/forms.py", line 180, in errors
    self.full_clean()
  File "/usr/lib/python3/dist-packages/django/forms/forms.py", line 381, in full_clean
    self._clean_fields()
  File "/usr/lib/python3/dist-packages/django/forms/forms.py", line 402, in _clean_fields
    value = getattr(self, 'clean_%s' % name)()
  File "/home/kali/Projects/Python_Projects/justice_law_office_django/parents/parent.py", line 103, in clean_nom
    return self.cleaned_data['nom'].upper()
AttributeError: 'NoneType' object has no attribute 'upper'
2021-10-07 15:55:45,621: ERROR [/usr/lib/python3/dist-packages/django/utils/log.py: log_response:222], django.request, log, 4718, 140020295923456, Internal Server Error: /departements/create
Traceback (most recent call last):
  File "/usr/lib/python3/dist-packages/django/core/handlers/exception.py", line 34, in inner
    response = get_response(request)
  File "/usr/lib/python3/dist-packages/django/core/handlers/base.py", line 115, in _get_response
    response = self.process_exception_by_middleware(e, request)
  File "/usr/lib/python3/dist-packages/django/core/handlers/base.py", line 113, in _get_response
    response = wrapped_callback(request, *callback_args, **callback_kwargs)
  File "/home/kali/Projects/Python_Projects/justice_law_office_django/affaires/views.py", line 315, in departement_form
    print('form.is_valid(): ', form.is_valid())
  File "/usr/lib/python3/dist-packages/django/forms/forms.py", line 185, in is_valid
    return self.is_bound and not self.errors
  File "/usr/lib/python3/dist-packages/django/forms/forms.py", line 180, in errors
    self.full_clean()
  File "/usr/lib/python3/dist-packages/django/forms/forms.py", line 381, in full_clean
    self._clean_fields()
  File "/usr/lib/python3/dist-packages/django/forms/forms.py", line 402, in _clean_fields
    value = getattr(self, 'clean_%s' % name)()
  File "/home/kali/Projects/Python_Projects/justice_law_office_django/parents/parent.py", line 103, in clean_nom
    return self.cleaned_data['nom'].upper()
AttributeError: 'NoneType' object has no attribute 'upper'
2021-10-07 16:05:06,820: ERROR [/usr/lib/python3/dist-packages/django/utils/log.py: log_response:222], django.request, log, 4798, 140656479561472, Internal Server Error: /departements/1/edit
Traceback (most recent call last):
  File "/usr/lib/python3/dist-packages/django/core/handlers/exception.py", line 34, in inner
    response = get_response(request)
  File "/usr/lib/python3/dist-packages/django/core/handlers/base.py", line 115, in _get_response
    response = self.process_exception_by_middleware(e, request)
  File "/usr/lib/python3/dist-packages/django/core/handlers/base.py", line 113, in _get_response
    response = wrapped_callback(request, *callback_args, **callback_kwargs)
  File "/home/kali/Projects/Python_Projects/justice_law_office_django/affaires/views.py", line 349, in departement_form
    return render(request=request, template_name=template_name, context=context)
  File "/usr/lib/python3/dist-packages/django/shortcuts.py", line 36, in render
    content = loader.render_to_string(template_name, context, request, using=using)
  File "/usr/lib/python3/dist-packages/django/template/loader.py", line 61, in render_to_string
    template = get_template(template_name, using=using)
  File "/usr/lib/python3/dist-packages/django/template/loader.py", line 19, in get_template
    raise TemplateDoesNotExist(template_name, chain=chain)
django.template.exceptions.TemplateDoesNotExist: affaires/departements/form.html
2021-10-07 16:05:12,183: ERROR [/usr/lib/python3/dist-packages/django/utils/log.py: log_response:222], django.request, log, 4798, 140656479561472, Internal Server Error: /departements/1/edit
Traceback (most recent call last):
  File "/usr/lib/python3/dist-packages/django/core/handlers/exception.py", line 34, in inner
    response = get_response(request)
  File "/usr/lib/python3/dist-packages/django/core/handlers/base.py", line 115, in _get_response
    response = self.process_exception_by_middleware(e, request)
  File "/usr/lib/python3/dist-packages/django/core/handlers/base.py", line 113, in _get_response
    response = wrapped_callback(request, *callback_args, **callback_kwargs)
  File "/home/kali/Projects/Python_Projects/justice_law_office_django/affaires/views.py", line 349, in departement_form
    return render(request=request, template_name=template_name, context=context)
  File "/usr/lib/python3/dist-packages/django/shortcuts.py", line 36, in render
    content = loader.render_to_string(template_name, context, request, using=using)
  File "/usr/lib/python3/dist-packages/django/template/loader.py", line 61, in render_to_string
    template = get_template(template_name, using=using)
  File "/usr/lib/python3/dist-packages/django/template/loader.py", line 19, in get_template
    raise TemplateDoesNotExist(template_name, chain=chain)
django.template.exceptions.TemplateDoesNotExist: affaires/departements/form.html
2021-10-07 16:08:59,589: ERROR [/usr/lib/python3/dist-packages/django/utils/log.py: log_response:222], django.request, log, 4798, 140656479561472, Internal Server Error: /departements/1/edit
Traceback (most recent call last):
  File "/usr/lib/python3/dist-packages/django/core/handlers/exception.py", line 34, in inner
    response = get_response(request)
  File "/usr/lib/python3/dist-packages/django/core/handlers/base.py", line 115, in _get_response
    response = self.process_exception_by_middleware(e, request)
  File "/usr/lib/python3/dist-packages/django/core/handlers/base.py", line 113, in _get_response
    response = wrapped_callback(request, *callback_args, **callback_kwargs)
  File "/home/kali/Projects/Python_Projects/justice_law_office_django/affaires/views.py", line 349, in departement_form
    return render(request=request, template_name=template_name, context=context)
  File "/usr/lib/python3/dist-packages/django/shortcuts.py", line 36, in render
    content = loader.render_to_string(template_name, context, request, using=using)
  File "/usr/lib/python3/dist-packages/django/template/loader.py", line 61, in render_to_string
    template = get_template(template_name, using=using)
  File "/usr/lib/python3/dist-packages/django/template/loader.py", line 19, in get_template
    raise TemplateDoesNotExist(template_name, chain=chain)
django.template.exceptions.TemplateDoesNotExist: affaires/departements/form.html
