2021-09-30 15:37:37,263: ERROR [/usr/lib/python3/dist-packages/django/utils/log.py: log_response:222], django.request, log, 5752, 139726099797760, Internal Server Error: /adversaires/1/edit
Traceback (most recent call last):
  File "/usr/lib/python3/dist-packages/django/core/handlers/exception.py", line 34, in inner
    response = get_response(request)
  File "/usr/lib/python3/dist-packages/django/core/handlers/base.py", line 115, in _get_response
    response = self.process_exception_by_middleware(e, request)
  File "/usr/lib/python3/dist-packages/django/core/handlers/base.py", line 113, in _get_response
    response = wrapped_callback(request, *callback_args, **callback_kwargs)
  File "/home/kali/Projects/Python_Projects/justice_law_office_django/adversaires/views.py", line 125, in adversaire_form
    form = AdversaireForm(instance=adversaire)
  File "/home/kali/Projects/Python_Projects/justice_law_office_django/adversaires/forms.py", line 14, in __init__
    super(AdversaireForm, self).__init__(*args, **kwargs)
  File "/home/kali/Projects/Python_Projects/justice_law_office_django/parents/parent.py", line 57, in __init__
    super(AdversaireForm, self).__init__(*args, **kwargs)
NameError: name 'AdversaireForm' is not defined
2021-09-30 15:39:42,714: ERROR [/usr/lib/python3/dist-packages/django/utils/log.py: log_response:222], django.request, log, 5858, 140105914337024, Internal Server Error: /adversaires/1/edit
Traceback (most recent call last):
  File "/usr/lib/python3/dist-packages/django/core/handlers/exception.py", line 34, in inner
    response = get_response(request)
  File "/usr/lib/python3/dist-packages/django/core/handlers/base.py", line 115, in _get_response
    response = self.process_exception_by_middleware(e, request)
  File "/usr/lib/python3/dist-packages/django/core/handlers/base.py", line 113, in _get_response
    response = wrapped_callback(request, *callback_args, **callback_kwargs)
  File "/home/kali/Projects/Python_Projects/justice_law_office_django/adversaires/views.py", line 125, in adversaire_form
    form = AdversaireForm(instance=adversaire)
  File "/home/kali/Projects/Python_Projects/justice_law_office_django/adversaires/forms.py", line 14, in __init__
    super(AdversaireForm, self).__init__(*args, **kwargs)
  File "/home/kali/Projects/Python_Projects/justice_law_office_django/parents/parent.py", line 57, in __init__
    super(AdversaireForm, self).__init__(*args, **kwargs)
NameError: name 'AdversaireForm' is not defined
2021-09-30 15:40:37,434: ERROR [/usr/lib/python3/dist-packages/django/utils/log.py: log_response:222], django.request, log, 5858, 140105914337024, Internal Server Error: /adversaires/1/edit
Traceback (most recent call last):
  File "/usr/lib/python3/dist-packages/django/core/handlers/exception.py", line 34, in inner
    response = get_response(request)
  File "/usr/lib/python3/dist-packages/django/core/handlers/base.py", line 115, in _get_response
    response = self.process_exception_by_middleware(e, request)
  File "/usr/lib/python3/dist-packages/django/core/handlers/base.py", line 113, in _get_response
    response = wrapped_callback(request, *callback_args, **callback_kwargs)
  File "/home/kali/Projects/Python_Projects/justice_law_office_django/adversaires/views.py", line 125, in adversaire_form
    form = AdversaireForm(instance=adversaire)
  File "/home/kali/Projects/Python_Projects/justice_law_office_django/adversaires/forms.py", line 14, in __init__
    super(AdversaireForm, self).__init__(*args, **kwargs)
  File "/home/kali/Projects/Python_Projects/justice_law_office_django/parents/parent.py", line 57, in __init__
    super(AdversaireForm, self).__init__(*args, **kwargs)
NameError: name 'AdversaireForm' is not defined
2021-09-30 17:04:05,100: ERROR [/usr/lib/python3/dist-packages/django/utils/log.py: log_response:222], django.request, log, 7184, 140445174396672, Internal Server Error: /adversaires/page/1/city/all/search/all-list
Traceback (most recent call last):
  File "/usr/lib/python3/dist-packages/django/core/handlers/exception.py", line 34, in inner
    response = get_response(request)
  File "/usr/lib/python3/dist-packages/django/core/handlers/base.py", line 115, in _get_response
    response = self.process_exception_by_middleware(e, request)
  File "/usr/lib/python3/dist-packages/django/core/handlers/base.py", line 113, in _get_response
    response = wrapped_callback(request, *callback_args, **callback_kwargs)
  File "/home/kali/Projects/Python_Projects/justice_law_office_django/adversaires/views.py", line 114, in justice_adversaires
    return render(request=request, template_name=template_name, context=context)
  File "/usr/lib/python3/dist-packages/django/shortcuts.py", line 36, in render
    content = loader.render_to_string(template_name, context, request, using=using)
  File "/usr/lib/python3/dist-packages/django/template/loader.py", line 62, in render_to_string
    return template.render(context, request)
  File "/usr/lib/python3/dist-packages/django/template/backends/django.py", line 61, in render
    return self.template.render(context)
  File "/usr/lib/python3/dist-packages/django/template/base.py", line 171, in render
    return self._render(context)
  File "/usr/lib/python3/dist-packages/django/template/base.py", line 163, in _render
    return self.nodelist.render(context)
  File "/usr/lib/python3/dist-packages/django/template/base.py", line 937, in render
    bit = node.render_annotated(context)
  File "/usr/lib/python3/dist-packages/django/template/base.py", line 904, in render_annotated
    return self.render(context)
  File "/usr/lib/python3/dist-packages/django/template/loader_tags.py", line 150, in render
    return compiled_parent._render(context)
  File "/usr/lib/python3/dist-packages/django/template/base.py", line 163, in _render
    return self.nodelist.render(context)
  File "/usr/lib/python3/dist-packages/django/template/base.py", line 937, in render
    bit = node.render_annotated(context)
  File "/usr/lib/python3/dist-packages/django/template/base.py", line 904, in render_annotated
    return self.render(context)
  File "/usr/lib/python3/dist-packages/django/template/loader_tags.py", line 150, in render
    return compiled_parent._render(context)
  File "/usr/lib/python3/dist-packages/django/template/base.py", line 163, in _render
    return self.nodelist.render(context)
  File "/usr/lib/python3/dist-packages/django/template/base.py", line 937, in render
    bit = node.render_annotated(context)
  File "/usr/lib/python3/dist-packages/django/template/base.py", line 904, in render_annotated
    return self.render(context)
  File "/usr/lib/python3/dist-packages/django/template/loader_tags.py", line 62, in render
    result = block.nodelist.render(context)
  File "/usr/lib/python3/dist-packages/django/template/base.py", line 937, in render
    bit = node.render_annotated(context)
  File "/usr/lib/python3/dist-packages/django/template/base.py", line 904, in render_annotated
    return self.render(context)
  File "/usr/lib/python3/dist-packages/django/template/loader_tags.py", line 62, in render
    result = block.nodelist.render(context)
  File "/usr/lib/python3/dist-packages/django/template/base.py", line 937, in render
    bit = node.render_annotated(context)
  File "/usr/lib/python3/dist-packages/django/template/base.py", line 904, in render_annotated
    return self.render(context)
  File "/usr/lib/python3/dist-packages/django/template/defaulttags.py", line 443, in render
    url = reverse(view_name, args=args, kwargs=kwargs, current_app=current_app)
  File "/usr/lib/python3/dist-packages/django/urls/base.py", line 90, in reverse
    return iri_to_uri(resolver._reverse_with_prefix(view, prefix, *args, **kwargs))
  File "/usr/lib/python3/dist-packages/django/urls/resolvers.py", line 673, in _reverse_with_prefix
    raise NoReverseMatch(msg)
django.urls.exceptions.NoReverseMatch: Reverse for 'justice_avocats_adversaires_all' not found. 'justice_avocats_adversaires_all' is not a valid view function or pattern name.
2021-09-30 17:04:15,449: ERROR [/usr/lib/python3/dist-packages/django/utils/log.py: log_response:222], django.request, log, 7184, 140445174396672, Internal Server Error: /adversaires/page/1/city/all/search/all-list
Traceback (most recent call last):
  File "/usr/lib/python3/dist-packages/django/core/handlers/exception.py", line 34, in inner
    response = get_response(request)
  File "/usr/lib/python3/dist-packages/django/core/handlers/base.py", line 115, in _get_response
    response = self.process_exception_by_middleware(e, request)
  File "/usr/lib/python3/dist-packages/django/core/handlers/base.py", line 113, in _get_response
    response = wrapped_callback(request, *callback_args, **callback_kwargs)
  File "/home/kali/Projects/Python_Projects/justice_law_office_django/adversaires/views.py", line 114, in justice_adversaires
    return render(request=request, template_name=template_name, context=context)
  File "/usr/lib/python3/dist-packages/django/shortcuts.py", line 36, in render
    content = loader.render_to_string(template_name, context, request, using=using)
  File "/usr/lib/python3/dist-packages/django/template/loader.py", line 62, in render_to_string
    return template.render(context, request)
  File "/usr/lib/python3/dist-packages/django/template/backends/django.py", line 61, in render
    return self.template.render(context)
  File "/usr/lib/python3/dist-packages/django/template/base.py", line 171, in render
    return self._render(context)
  File "/usr/lib/python3/dist-packages/django/template/base.py", line 163, in _render
    return self.nodelist.render(context)
  File "/usr/lib/python3/dist-packages/django/template/base.py", line 937, in render
    bit = node.render_annotated(context)
  File "/usr/lib/python3/dist-packages/django/template/base.py", line 904, in render_annotated
    return self.render(context)
  File "/usr/lib/python3/dist-packages/django/template/loader_tags.py", line 150, in render
    return compiled_parent._render(context)
  File "/usr/lib/python3/dist-packages/django/template/base.py", line 163, in _render
    return self.nodelist.render(context)
  File "/usr/lib/python3/dist-packages/django/template/base.py", line 937, in render
    bit = node.render_annotated(context)
  File "/usr/lib/python3/dist-packages/django/template/base.py", line 904, in render_annotated
    return self.render(context)
  File "/usr/lib/python3/dist-packages/django/template/loader_tags.py", line 150, in render
    return compiled_parent._render(context)
  File "/usr/lib/python3/dist-packages/django/template/base.py", line 163, in _render
    return self.nodelist.render(context)
  File "/usr/lib/python3/dist-packages/django/template/base.py", line 937, in render
    bit = node.render_annotated(context)
  File "/usr/lib/python3/dist-packages/django/template/base.py", line 904, in render_annotated
    return self.render(context)
  File "/usr/lib/python3/dist-packages/django/template/loader_tags.py", line 62, in render
    result = block.nodelist.render(context)
  File "/usr/lib/python3/dist-packages/django/template/base.py", line 937, in render
    bit = node.render_annotated(context)
  File "/usr/lib/python3/dist-packages/django/template/base.py", line 904, in render_annotated
    return self.render(context)
  File "/usr/lib/python3/dist-packages/django/template/loader_tags.py", line 62, in render
    result = block.nodelist.render(context)
  File "/usr/lib/python3/dist-packages/django/template/base.py", line 937, in render
    bit = node.render_annotated(context)
  File "/usr/lib/python3/dist-packages/django/template/base.py", line 904, in render_annotated
    return self.render(context)
  File "/usr/lib/python3/dist-packages/django/template/defaulttags.py", line 443, in render
    url = reverse(view_name, args=args, kwargs=kwargs, current_app=current_app)
  File "/usr/lib/python3/dist-packages/django/urls/base.py", line 90, in reverse
    return iri_to_uri(resolver._reverse_with_prefix(view, prefix, *args, **kwargs))
  File "/usr/lib/python3/dist-packages/django/urls/resolvers.py", line 673, in _reverse_with_prefix
    raise NoReverseMatch(msg)
django.urls.exceptions.NoReverseMatch: Reverse for 'justice_avocats_adversaires_all' not found. 'justice_avocats_adversaires_all' is not a valid view function or pattern name.
2021-09-30 17:11:58,530: ERROR [/usr/lib/python3/dist-packages/django/utils/log.py: log_response:222], django.request, log, 7184, 140445086639872, Internal Server Error: /adversaires/page/1/city/all/search/all-list
Traceback (most recent call last):
  File "/usr/lib/python3/dist-packages/django/core/handlers/exception.py", line 34, in inner
    response = get_response(request)
  File "/usr/lib/python3/dist-packages/django/core/handlers/base.py", line 115, in _get_response
    response = self.process_exception_by_middleware(e, request)
  File "/usr/lib/python3/dist-packages/django/core/handlers/base.py", line 113, in _get_response
    response = wrapped_callback(request, *callback_args, **callback_kwargs)
  File "/home/kali/Projects/Python_Projects/justice_law_office_django/adversaires/views.py", line 114, in justice_adversaires
    return render(request=request, template_name=template_name, context=context)
  File "/usr/lib/python3/dist-packages/django/shortcuts.py", line 36, in render
    content = loader.render_to_string(template_name, context, request, using=using)
  File "/usr/lib/python3/dist-packages/django/template/loader.py", line 62, in render_to_string
    return template.render(context, request)
  File "/usr/lib/python3/dist-packages/django/template/backends/django.py", line 61, in render
    return self.template.render(context)
  File "/usr/lib/python3/dist-packages/django/template/base.py", line 171, in render
    return self._render(context)
  File "/usr/lib/python3/dist-packages/django/template/base.py", line 163, in _render
    return self.nodelist.render(context)
  File "/usr/lib/python3/dist-packages/django/template/base.py", line 937, in render
    bit = node.render_annotated(context)
  File "/usr/lib/python3/dist-packages/django/template/base.py", line 904, in render_annotated
    return self.render(context)
  File "/usr/lib/python3/dist-packages/django/template/loader_tags.py", line 150, in render
    return compiled_parent._render(context)
  File "/usr/lib/python3/dist-packages/django/template/base.py", line 163, in _render
    return self.nodelist.render(context)
  File "/usr/lib/python3/dist-packages/django/template/base.py", line 937, in render
    bit = node.render_annotated(context)
  File "/usr/lib/python3/dist-packages/django/template/base.py", line 904, in render_annotated
    return self.render(context)
  File "/usr/lib/python3/dist-packages/django/template/loader_tags.py", line 150, in render
    return compiled_parent._render(context)
  File "/usr/lib/python3/dist-packages/django/template/base.py", line 163, in _render
    return self.nodelist.render(context)
  File "/usr/lib/python3/dist-packages/django/template/base.py", line 937, in render
    bit = node.render_annotated(context)
  File "/usr/lib/python3/dist-packages/django/template/base.py", line 904, in render_annotated
    return self.render(context)
  File "/usr/lib/python3/dist-packages/django/template/loader_tags.py", line 62, in render
    result = block.nodelist.render(context)
  File "/usr/lib/python3/dist-packages/django/template/base.py", line 937, in render
    bit = node.render_annotated(context)
  File "/usr/lib/python3/dist-packages/django/template/base.py", line 904, in render_annotated
    return self.render(context)
  File "/usr/lib/python3/dist-packages/django/template/defaulttags.py", line 443, in render
    url = reverse(view_name, args=args, kwargs=kwargs, current_app=current_app)
  File "/usr/lib/python3/dist-packages/django/urls/base.py", line 90, in reverse
    return iri_to_uri(resolver._reverse_with_prefix(view, prefix, *args, **kwargs))
  File "/usr/lib/python3/dist-packages/django/urls/resolvers.py", line 673, in _reverse_with_prefix
    raise NoReverseMatch(msg)
django.urls.exceptions.NoReverseMatch: Reverse for 'justice_avocats_adversaires_all' not found. 'justice_avocats_adversaires_all' is not a valid view function or pattern name.
2021-09-30 17:12:15,155: ERROR [/usr/lib/python3/dist-packages/django/utils/log.py: log_response:222], django.request, log, 7184, 140445086639872, Internal Server Error: /
Traceback (most recent call last):
  File "/usr/lib/python3/dist-packages/django/core/handlers/exception.py", line 34, in inner
    response = get_response(request)
  File "/usr/lib/python3/dist-packages/django/core/handlers/base.py", line 115, in _get_response
    response = self.process_exception_by_middleware(e, request)
  File "/usr/lib/python3/dist-packages/django/core/handlers/base.py", line 113, in _get_response
    response = wrapped_callback(request, *callback_args, **callback_kwargs)
  File "/home/kali/Projects/Python_Projects/justice_law_office_django/justice/views.py", line 13, in index
    return render(request=request, template_name=template_name, context=context)
  File "/usr/lib/python3/dist-packages/django/shortcuts.py", line 36, in render
    content = loader.render_to_string(template_name, context, request, using=using)
  File "/usr/lib/python3/dist-packages/django/template/loader.py", line 62, in render_to_string
    return template.render(context, request)
  File "/usr/lib/python3/dist-packages/django/template/backends/django.py", line 61, in render
    return self.template.render(context)
  File "/usr/lib/python3/dist-packages/django/template/base.py", line 171, in render
    return self._render(context)
  File "/usr/lib/python3/dist-packages/django/template/base.py", line 163, in _render
    return self.nodelist.render(context)
  File "/usr/lib/python3/dist-packages/django/template/base.py", line 937, in render
    bit = node.render_annotated(context)
  File "/usr/lib/python3/dist-packages/django/template/base.py", line 904, in render_annotated
    return self.render(context)
  File "/usr/lib/python3/dist-packages/django/template/loader_tags.py", line 150, in render
    return compiled_parent._render(context)
  File "/usr/lib/python3/dist-packages/django/template/base.py", line 163, in _render
    return self.nodelist.render(context)
  File "/usr/lib/python3/dist-packages/django/template/base.py", line 937, in render
    bit = node.render_annotated(context)
  File "/usr/lib/python3/dist-packages/django/template/base.py", line 904, in render_annotated
    return self.render(context)
  File "/usr/lib/python3/dist-packages/django/template/loader_tags.py", line 150, in render
    return compiled_parent._render(context)
  File "/usr/lib/python3/dist-packages/django/template/base.py", line 163, in _render
    return self.nodelist.render(context)
  File "/usr/lib/python3/dist-packages/django/template/base.py", line 937, in render
    bit = node.render_annotated(context)
  File "/usr/lib/python3/dist-packages/django/template/base.py", line 904, in render_annotated
    return self.render(context)
  File "/usr/lib/python3/dist-packages/django/template/loader_tags.py", line 62, in render
    result = block.nodelist.render(context)
  File "/usr/lib/python3/dist-packages/django/template/base.py", line 937, in render
    bit = node.render_annotated(context)
  File "/usr/lib/python3/dist-packages/django/template/base.py", line 904, in render_annotated
    return self.render(context)
  File "/usr/lib/python3/dist-packages/django/template/defaulttags.py", line 443, in render
    url = reverse(view_name, args=args, kwargs=kwargs, current_app=current_app)
  File "/usr/lib/python3/dist-packages/django/urls/base.py", line 90, in reverse
    return iri_to_uri(resolver._reverse_with_prefix(view, prefix, *args, **kwargs))
  File "/usr/lib/python3/dist-packages/django/urls/resolvers.py", line 673, in _reverse_with_prefix
    raise NoReverseMatch(msg)
django.urls.exceptions.NoReverseMatch: Reverse for 'justice_avocats_adversaires_all' not found. 'justice_avocats_adversaires_all' is not a valid view function or pattern name.
2021-09-30 17:12:19,877: ERROR [/usr/lib/python3/dist-packages/django/utils/log.py: log_response:222], django.request, log, 7184, 140445086639872, Internal Server Error: /
Traceback (most recent call last):
  File "/usr/lib/python3/dist-packages/django/core/handlers/exception.py", line 34, in inner
    response = get_response(request)
  File "/usr/lib/python3/dist-packages/django/core/handlers/base.py", line 115, in _get_response
    response = self.process_exception_by_middleware(e, request)
  File "/usr/lib/python3/dist-packages/django/core/handlers/base.py", line 113, in _get_response
    response = wrapped_callback(request, *callback_args, **callback_kwargs)
  File "/home/kali/Projects/Python_Projects/justice_law_office_django/justice/views.py", line 13, in index
    return render(request=request, template_name=template_name, context=context)
  File "/usr/lib/python3/dist-packages/django/shortcuts.py", line 36, in render
    content = loader.render_to_string(template_name, context, request, using=using)
  File "/usr/lib/python3/dist-packages/django/template/loader.py", line 62, in render_to_string
    return template.render(context, request)
  File "/usr/lib/python3/dist-packages/django/template/backends/django.py", line 61, in render
    return self.template.render(context)
  File "/usr/lib/python3/dist-packages/django/template/base.py", line 171, in render
    return self._render(context)
  File "/usr/lib/python3/dist-packages/django/template/base.py", line 163, in _render
    return self.nodelist.render(context)
  File "/usr/lib/python3/dist-packages/django/template/base.py", line 937, in render
    bit = node.render_annotated(context)
  File "/usr/lib/python3/dist-packages/django/template/base.py", line 904, in render_annotated
    return self.render(context)
  File "/usr/lib/python3/dist-packages/django/template/loader_tags.py", line 150, in render
    return compiled_parent._render(context)
  File "/usr/lib/python3/dist-packages/django/template/base.py", line 163, in _render
    return self.nodelist.render(context)
  File "/usr/lib/python3/dist-packages/django/template/base.py", line 937, in render
    bit = node.render_annotated(context)
  File "/usr/lib/python3/dist-packages/django/template/base.py", line 904, in render_annotated
    return self.render(context)
  File "/usr/lib/python3/dist-packages/django/template/loader_tags.py", line 150, in render
    return compiled_parent._render(context)
  File "/usr/lib/python3/dist-packages/django/template/base.py", line 163, in _render
    return self.nodelist.render(context)
  File "/usr/lib/python3/dist-packages/django/template/base.py", line 937, in render
    bit = node.render_annotated(context)
  File "/usr/lib/python3/dist-packages/django/template/base.py", line 904, in render_annotated
    return self.render(context)
  File "/usr/lib/python3/dist-packages/django/template/loader_tags.py", line 62, in render
    result = block.nodelist.render(context)
  File "/usr/lib/python3/dist-packages/django/template/base.py", line 937, in render
    bit = node.render_annotated(context)
  File "/usr/lib/python3/dist-packages/django/template/base.py", line 904, in render_annotated
    return self.render(context)
  File "/usr/lib/python3/dist-packages/django/template/defaulttags.py", line 443, in render
    url = reverse(view_name, args=args, kwargs=kwargs, current_app=current_app)
  File "/usr/lib/python3/dist-packages/django/urls/base.py", line 90, in reverse
    return iri_to_uri(resolver._reverse_with_prefix(view, prefix, *args, **kwargs))
  File "/usr/lib/python3/dist-packages/django/urls/resolvers.py", line 673, in _reverse_with_prefix
    raise NoReverseMatch(msg)
django.urls.exceptions.NoReverseMatch: Reverse for 'justice_avocats_adversaires_all' not found. 'justice_avocats_adversaires_all' is not a valid view function or pattern name.
